Traceback (most recent call last):
  File "/Users/yuchiaol_ntuas/miniconda3/lib/python3.11/site-packages/jupyter_cache/executors/utils.py", line 58, in single_nb_execution
    executenb(
  File "/Users/yuchiaol_ntuas/miniconda3/lib/python3.11/site-packages/nbclient/client.py", line 1305, in execute
    return NotebookClient(nb=nb, resources=resources, km=km, **kwargs).execute()
           ^^^^^^^^^^^^^^^^^^^^^^^^^^^^^^^^^^^^^^^^^^^^^^^^^^^^^^^^^^^^^^^^^^^^^
  File "/Users/yuchiaol_ntuas/miniconda3/lib/python3.11/site-packages/jupyter_core/utils/__init__.py", line 166, in wrapped
    return loop.run_until_complete(inner)
           ^^^^^^^^^^^^^^^^^^^^^^^^^^^^^^
  File "/Users/yuchiaol_ntuas/miniconda3/lib/python3.11/asyncio/base_events.py", line 653, in run_until_complete
    return future.result()
           ^^^^^^^^^^^^^^^
  File "/Users/yuchiaol_ntuas/miniconda3/lib/python3.11/site-packages/nbclient/client.py", line 705, in async_execute
    await self.async_execute_cell(
  File "/Users/yuchiaol_ntuas/miniconda3/lib/python3.11/site-packages/nbclient/client.py", line 1058, in async_execute_cell
    await self._check_raise_for_error(cell, cell_index, exec_reply)
  File "/Users/yuchiaol_ntuas/miniconda3/lib/python3.11/site-packages/nbclient/client.py", line 914, in _check_raise_for_error
    raise CellExecutionError.from_cell_and_msg(cell, exec_reply_content)
nbclient.exceptions.CellExecutionError: An error occurred while executing the following cell:
------------------
import numpy as np
   nx = 20
   Q = 341.3 # W / m^2   
   sigma = 5.67e-8 # W / m^2 / K^4
   alpha = np.linspace(0,1,nx)
   tau = np.linspace(0.1,1,nx)

   Teq_obs = ((1-0.3)*Q/0.61/sigma)**0.25

   Teq = np.zeros((nx,nx))
   for JJ in range(nx):
       for II in range(nx):
           Teq[JJ,II] = ((1-alpha[JJ])*Q/tau[II]/sigma)**0.25
------------------


[0;36m  Cell [0;32mIn[1], line 2[0;36m[0m
[0;31m    nx = 20[0m
[0m    ^[0m
[0;31mIndentationError[0m[0;31m:[0m unexpected indent


